<?xml version='1.0' encoding='utf-8'?>
<robot name="t1">
  <link name="Trunk">
    <inertial>
      <origin xyz="0.0551365401093076 -1.42058017623659E-06 0.105062332707657" />
      <mass value="11.7" />
      <inertia ixx="0.0915287235057927" ixy="-4.25369739206781E-07" ixz="0.000646360369011163" iyy="0.076778716903413" iyz="5.82340020271393E-07" izz="0.0556171053368987" />
    </inertial>
    <visual>
      <geometry>
        <mesh filename="meshes/Trunk.obj" />
      </geometry>
    </visual>
    <collision>
      <origin xyz="0.06 0 0.12" />
      <geometry>
        <box size="0.15 0.2 0.3" />
      </geometry>
    </collision>
  </link>
  <link name="H1">
    <inertial>
      <origin xyz="-0.000508 -0.001403 0.057432" />
      <mass value="0.443910" />
      <inertia ixx="0.000224" ixy="0.000003" ixz="0.000001" iyy="0.000241" iyz="-0.000002" izz="0.000150" />
    </inertial>
    <visual>
      <geometry>
        <mesh filename="meshes/H1.obj" />
      </geometry>
    </visual>
  </link>
  <joint name="AAHead_yaw" type="revolute">
    <origin xyz="0.0625 0 0.243" />
    <parent link="Trunk" />
    <child link="H1" />
    <axis xyz="0 0 1" />
    <limit lower="-1.57" upper="1.57" effort="7" velocity="12.56" />
  </joint>
  <link name="H2">
    <inertial>
      <origin xyz="0.007802 0.001262 0.098631" />
      <mass value="0.631019" />
      <inertia ixx="0.002025" ixy="-0.000025" ixz="0.000046" iyy="0.001920" iyz="0.000036" izz="0.001739" />
    </inertial>
    <visual>
      <geometry>
        <mesh filename="meshes/H2.obj" />
      </geometry>
    </visual>
    <collision>
      <origin xyz="0.01 0 0.11" />
      <geometry>
        <sphere radius="0.08" />
      </geometry>
    </collision>
  </link>
  <joint name="Head_pitch" type="revolute">
    <origin xyz="0 0 0.06185" />
    <parent link="H1" />
    <child link="H2" />
    <axis xyz="0 1 0" />
    <limit lower="-0.35" upper="1.22" effort="7" velocity="12.56" />
  </joint>
  <link name="AL1">
    <inertial>
      <origin xyz="-0.000677 0.044974 0.000000" />
      <mass value="0.53" />
      <inertia ixx="0.001293" ixy="-0.000017" ixz="0.000000" iyy="0.000293" iyz="0.000000" izz="0.001367" />
    </inertial>
    <visual>
      <geometry>
        <mesh filename="meshes/AL1.obj" />
      </geometry>
    </visual>
  </link>
  <joint name="Left_Shoulder_Pitch" type="revolute">
    <origin xyz="0.0575 0.1063 0.219" rpy="0 0.00088113 0" />
    <parent link="Trunk" />
    <child link="AL1" />
    <axis xyz="0 1 0" />
    <limit lower="-3.31" upper="1.22" effort="18" velocity="18.84" />
  </joint>
  <link name="AL2">
    <inertial>
      <origin xyz="0.003862 0.037976 0.000000" />
      <mass value="0.160" />
      <inertia ixx="0.000345" ixy="0.000008" ixz="0.000000" iyy="0.000177" iyz="0.000000" izz="0.000401" />
    </inertial>
    <visual>
      <geometry>
        <mesh filename="meshes/AL2.obj" />
      </geometry>
    </visual>
  </link>
  <joint name="Left_Shoulder_Roll" type="revolute">
    <origin xyz="0 0.047 0" />
    <parent link="AL1" />
    <child link="AL2" />
    <axis xyz="1 0 0" />
    <limit lower="-1.74" upper="1.57" effort="18" velocity="18.84" />
  </joint>
  <link name="AL3">
    <inertial>
      <origin xyz="0.000000 0.085353 -0.000099" />
      <mass value="1.02" />
      <inertia ixx="0.012869" ixy="0.000000" ixz="0.000000" iyy="0.000621" iyz="-0.000024" izz="0.012798" />
    </inertial>
    <visual>
      <geometry>
        <mesh filename="meshes/AL3.obj" />
      </geometry>
    </visual>
    <collision>
      <origin xyz="0 0.05 0" rpy="1.5708 0 0" />
      <geometry>
        <cylinder radius="0.03" length="0.15" />
      </geometry>
    </collision>
  </link>
  <joint name="Left_Elbow_Pitch" type="revolute">
    <origin xyz="0.00025 0.0605 0" />
    <parent link="AL2" />
    <child link="AL3" />
    <axis xyz="0 1 0" />
    <limit lower="-2.27" upper="2.27" effort="18" velocity="18.84" />
  </joint>
  <joint name="Left_Elbow_Yaw" type="revolute">
    <origin xyz="0 0.1471 0" />
    <parent link="AL3" />
    <child link="left_hand_base" />
    <axis xyz="0 0 1" />
    <limit lower="-2.44" upper="0" effort="18" velocity="18.84" />
  </joint>
  <link name="AR1">
    <inertial>
      <origin xyz="-0.000677 -0.044974 0.000000" />
      <mass value="0.53" />
      <inertia ixx="0.001293" ixy="-0.000017" ixz="0.000000" iyy="0.000293" iyz="0.000000" izz="0.001367" />
    </inertial>
    <visual>
      <geometry>
        <mesh filename="meshes/AR1.obj" />
      </geometry>
    </visual>
  </link>
  <joint name="Right_Shoulder_Pitch" type="revolute">
    <origin xyz="0.0575 -0.1063 0.219" rpy="0 0.00088113 0" />
    <parent link="Trunk" />
    <child link="AR1" />
    <axis xyz="0 1 0" />
    <limit lower="-3.31" upper="1.22" effort="18" velocity="18.84" />
  </joint>
  <link name="AR2">
    <inertial>
      <origin xyz="0.003862 -0.037976 0.000000" />
      <mass value="0.160" />
      <inertia ixx="0.000345" ixy="-0.000008" ixz="0.000000" iyy="0.000177" iyz="0.000000" izz="0.000401" />
    </inertial>
    <visual>
      <geometry>
        <mesh filename="meshes/AR2.obj" />
      </geometry>
    </visual>
  </link>
  <joint name="Right_Shoulder_Roll" type="revolute">
    <origin xyz="0 -0.047 0" />
    <parent link="AR1" />
    <child link="AR2" />
    <axis xyz="1 0 0" />
    <limit lower="-1.57" upper="1.74" effort="18" velocity="18.84" />
  </joint>
  <link name="AR3">
    <inertial>
      <origin xyz="0.000000 -0.085353 -0.000099" />
      <mass value="1.02" />
      <inertia ixx="0.012869" ixy="0.000000" ixz="0.000000" iyy="0.000621" iyz="0.000024" izz="0.012798" />
    </inertial>
    <visual>
      <geometry>
        <mesh filename="meshes/AR3.obj" />
      </geometry>
    </visual>
    <collision>
      <origin xyz="0 -0.05 0" rpy="1.5708 0 0" />
      <geometry>
        <cylinder radius="0.03" length="0.15" />
      </geometry>
    </collision>
  </link>
  <joint name="Right_Elbow_Pitch" type="revolute">
    <origin xyz="0.00025 -0.0605 0" />
    <parent link="AR2" />
    <child link="AR3" />
    <axis xyz="0 1 0" />
    <limit lower="-2.27" upper="2.27" effort="18" velocity="18.84" />
  </joint>
  <joint name="Right_Elbow_Yaw" type="revolute">
    <origin xyz="0 -0.1471 0" />
    <parent link="AR3" />
    <child link="right_hand_base" />
    <axis xyz="0 0 1" />
    <limit lower="0" upper="2.44" effort="18" velocity="18.84" />
  </joint>
  <link name="Waist">
    <inertial>
      <origin xyz="0.002284 0.000003 0.007301" />
      <mass value="2.581" />
      <inertia ixx="0.005289" ixy="0.000000" ixz="0.000207" iyy="0.005299" iyz="0.000001" izz="0.004821" />
    </inertial>
    <visual>
      <geometry>
        <mesh filename="meshes/Waist.obj" />
      </geometry>
    </visual>
  </link>
  <joint name="Waist" type="revolute">
    <origin xyz="0.0625 0 -0.1155" />
    <parent link="Trunk" />
    <child link="Waist" />
    <axis xyz="0 0 1" />
    <limit lower="-1.57" upper="1.57" effort="30" velocity="10.88" />
  </joint>
  <link name="Hip_Pitch_Left">
    <inertial>
      <origin xyz="0.000534 -0.007296 -0.018083" />
      <mass value="1.021" />
      <inertia ixx="0.001805" ixy="0.000006" ixz="-0.000015" iyy="0.001421" iyz="0.000080" izz="0.001292" />
    </inertial>
    <visual>
      <geometry>
        <mesh filename="meshes/Hip_pitch_left.obj" />
      </geometry>
    </visual>
  </link>
  <joint name="Left_Hip_Pitch" type="revolute">
    <origin xyz="0 0.106 0" />
    <parent link="Waist" />
    <child link="Hip_Pitch_Left" />
    <axis xyz="0 1 0" />
    <limit lower="-1.8" upper="1.57" effort="45" velocity="12.5" />
  </joint>
  <link name="Hip_Roll_Left">
    <inertial>
      <origin xyz="0.001101 0.000024 -0.053750" />
      <mass value="0.385" />
      <inertia ixx="0.001517" ixy="0.000000" ixz="0.000017" iyy="0.001743" iyz="0.000000" izz="0.000515" />
    </inertial>
    <visual>
      <geometry>
        <mesh filename="meshes/Hip_roll_left.obj" />
      </geometry>
    </visual>
  </link>
  <joint name="Left_Hip_Roll" type="revolute">
    <origin xyz="0 0 -0.02" />
    <parent link="Hip_Pitch_Left" />
    <child link="Hip_Roll_Left" />
    <axis xyz="1 0 0" />
    <limit lower="-0.2" upper="1.57" effort="30" velocity="10.9" />
  </joint>
  <link name="Hip_Yaw_Left">
    <inertial>
      <origin xyz="-0.007233 0.000206 -0.089184" />
      <mass value="2.166" />
      <inertia ixx="0.025108" ixy="-0.000007" ixz="0.002094" iyy="0.025733" iyz="-0.000050" izz="0.002787" />
    </inertial>
    <visual>
      <geometry>
        <mesh filename="meshes/Hip_yaw.obj" />
      </geometry>
    </visual>
    <collision>
      <origin xyz="0 0 0" />
      <geometry>
        <cylinder radius="0.05" length="0.16" />
      </geometry>
    </collision>
  </link>
  <joint name="Left_Hip_Yaw" type="revolute">
    <origin xyz="0 0 -0.081854" />
    <parent link="Hip_Roll_Left" />
    <child link="Hip_Yaw_Left" />
    <axis xyz="0 0 1" />
    <limit lower="-1" upper="1" effort="30" velocity="10.9" />
  </joint>
  <link name="Shank_Left">
    <inertial>
      <origin xyz="-0.006012 0.000259 -0.124318" />
      <mass value="1.73" />
      <inertia ixx="0.034618" ixy="0.000011" ixz="0.001561" iyy="0.034539" iyz="0.000197" izz="0.001934" />
    </inertial>
    <visual>
      <geometry>
        <mesh filename="meshes/Shank_left.obj" />
      </geometry>
    </visual>
    <collision>
      <origin xyz="0 0 -0.12" />
      <geometry>
        <cylinder radius="0.05" length="0.15" />
      </geometry>
    </collision>
  </link>
  <joint name="Left_Knee_Pitch" type="revolute">
    <origin xyz="-0.014 0 -0.134" />
    <parent link="Hip_Yaw_Left" />
    <child link="Shank_Left" />
    <axis xyz="0 1 0" />
    <limit lower="0" upper="2.34" effort="60" velocity="11.7" />
  </joint>
  <link name="Ankle_Cross_Left">
    <inertial>
      <origin xyz="-0.003722 0.000000 -0.007981" />
      <mass value="0.073" />
      <inertia ixx="0.000012" ixy="0.000000" ixz="0.000003" iyy="0.000029" iyz="0.000000" izz="0.000025" />
    </inertial>
    <visual>
      <geometry>
        <mesh filename="meshes/Ankle_cross_left.obj" />
      </geometry>
    </visual>
  </link>
  <joint name="Left_Ankle_Pitch" type="revolute">
    <origin xyz="0 0 -0.28" />
    <parent link="Shank_Left" />
    <child link="Ankle_Cross_Left" />
    <axis xyz="0 1 0" />
    <limit lower="-0.87" upper="0.35" effort="20" velocity="18.8" />
  </joint>
  <link name="left_foot_link">
    <inertial>
      <origin xyz="-0.000249 0.000000 -0.009140" />
      <mass value="0.685" />
      <inertia ixx="0.002214" ixy="0" ixz="-0.000114" iyy="0.002385" iyz="0" izz="0.002671" />
    </inertial>
    <visual>
      <geometry>
        <mesh filename="meshes/Foot_link.obj" />
      </geometry>
    </visual>
    <collision>
      <origin xyz="0.01 0 -0.015" />
      <geometry>
        <box size="0.223 0.1 0.03" />
      </geometry>
    </collision>
  </link>
  <joint name="Left_Ankle_Roll" type="revolute">
    <origin xyz="0 0.00025 -0.012" />
    <parent link="Ankle_Cross_Left" />
    <child link="left_foot_link" />
    <axis xyz="1 0 0" />
    <limit lower="-0.44" upper="0.44" effort="15" velocity="12.4" />
  </joint>
  <link name="Hip_Pitch_Right">
    <inertial>
      <origin xyz="0.000534 0.007514 -0.018082" />
      <mass value="1.021" />
      <inertia ixx="0.001805" ixy="-0.000008" ixz="-0.000015" iyy="0.001421" iyz="-0.000085" izz="0.001292" />
    </inertial>
    <visual>
      <geometry>
        <mesh filename="meshes/Hip_pitch_right.obj" />
      </geometry>
    </visual>
  </link>
  <joint name="Right_Hip_Pitch" type="revolute">
    <origin xyz="0 -0.106 0" />
    <parent link="Waist" />
    <child link="Hip_Pitch_Right" />
    <axis xyz="0 1 0" />
    <limit lower="-1.8" upper="1.57" effort="45" velocity="12.5" />
  </joint>
  <link name="Hip_Roll_Right">
    <inertial>
      <origin xyz="0.001099 0.000024 -0.053748" />
      <mass value="0.385" />
      <inertia ixx="0.001517" ixy="0.000000" ixz="0.000017" iyy="0.001743" iyz="0.000000" izz="0.000515" />
    </inertial>
    <visual>
      <geometry>
        <mesh filename="meshes/Hip_roll_right.obj" />
      </geometry>
    </visual>
  </link>
  <joint name="Right_Hip_Roll" type="revolute">
    <origin xyz="0 0 -0.02" />
    <parent link="Hip_Pitch_Right" />
    <child link="Hip_Roll_Right" />
    <axis xyz="1 0 0" />
    <limit lower="-1.57" upper="0.2" effort="30" velocity="10.9" />
  </joint>
  <link name="Hip_Yaw_Right">
    <inertial>
      <origin xyz="-0.007191 -0.000149 -0.089220" />
      <mass value="2.17" />
      <inertia ixx="0.025137" ixy="0.000006" ixz="0.002086" iyy="0.025762" iyz="0.000044" izz="0.002787" />
    </inertial>
    <visual>
      <geometry>
        <mesh filename="meshes/Hip_yaw.obj" />
      </geometry>
    </visual>
    <collision>
      <origin xyz="0 0 0" />
      <geometry>
        <cylinder radius="0.05" length="0.16" />
      </geometry>
    </collision>
  </link>
  <joint name="Right_Hip_Yaw" type="revolute">
    <origin xyz="0 0 -0.081854" />
    <parent link="Hip_Roll_Right" />
    <child link="Hip_Yaw_Right" />
    <axis xyz="0 0 1" />
    <limit lower="-1" upper="1" effort="30" velocity="10.9" />
  </joint>
  <link name="Shank_Right">
    <inertial>
      <origin xyz="-0.005741 -0.000541 -0.122602" />
      <mass value="1.79" />
      <inertia ixx="0.035098" ixy="-0.000009" ixz="0.001554" iyy="0.034958" iyz="-0.000086" izz="0.002039" />
    </inertial>
    <visual>
      <geometry>
        <mesh filename="meshes/Shank_right.obj" />
      </geometry>
    </visual>
    <collision>
      <origin xyz="0 0 -0.12" />
      <geometry>
        <cylinder radius="0.05" length="0.15" />
      </geometry>
    </collision>
  </link>
  <joint name="Right_Knee_Pitch" type="revolute">
    <origin xyz="-0.014 0 -0.134" />
    <parent link="Hip_Yaw_Right" />
    <child link="Shank_Right" />
    <axis xyz="0 1 0" />
    <limit lower="0" upper="2.34" effort="60" velocity="11.7" />
  </joint>
  <link name="Ankle_Cross_Right">
    <inertial>
      <origin xyz="-0.003722 0.000000 -0.007981" />
      <mass value="0.073" />
      <inertia ixx="0.000012" ixy="0.000000" ixz="0.000003" iyy="0.000029" iyz="0.000000" izz="0.000025" />
    </inertial>
    <visual>
      <geometry>
        <mesh filename="meshes/Ankle_cross_right.obj" />
      </geometry>
    </visual>
  </link>
  <joint name="Right_Ankle_Pitch" type="revolute">
    <origin xyz="0 0 -0.28" />
    <parent link="Shank_Right" />
    <child link="Ankle_Cross_Right" />
    <axis xyz="0 1 0" />
    <limit lower="-0.87" upper="0.35" effort="20" velocity="18.8" />
  </joint>
  <link name="right_foot_link">
    <inertial>
      <origin xyz="-0.000248 0.000000 -0.009140" />
      <mass value="0.685" />
      <inertia ixx="0.002214" ixy="0" ixz="-0.000114" iyy="0.002385" iyz="0" izz="0.002671" />
    </inertial>
    <visual>
      <geometry>
        <mesh filename="meshes/Foot_link.obj" />
      </geometry>
    </visual>
    <collision>
      <origin xyz="0.01 0 -0.015" />
      <geometry>
        <box size="0.223 0.1 0.03" />
      </geometry>
    </collision>
  </link>
  <joint name="Right_Ankle_Roll" type="revolute">
    <origin xyz="0 -0.00025 -0.012" />
    <parent link="Ankle_Cross_Right" />
    <child link="right_foot_link" />
    <axis xyz="1 0 0" />
    <limit lower="-0.44" upper="0.44" effort="15" velocity="12.4" />
  </joint>
  <link name="left_hand_base">
    <inertial>
      <origin xyz="2e-05 -0.0024500000000000004 0.07793000000000001" rpy="0 0 0" />
      <mass value="0.6273500000000001" />
      <inertia ixx="0.0014968368000000001" ixy="1.64393e-06" ixz="-2.527401e-05" iyy="0.0017872599099999999" iyz="0.00012212543" izz="0.00071434062" />
    </inertial>
    <visual>
      <origin xyz="0 0 0" rpy="0 0 0" />
      <geometry>
        <mesh filename="meshes/left_hand/base_link.STL" />
      </geometry>
      <material name="">
        <color rgba="1 1 1 1" />
      </material>
    </visual>
    <collision>
      <origin xyz="0 0 0" rpy="0 0 0" />
      <geometry>
        <mesh filename="meshes/left_hand/base_link.STL" />
      </geometry>
    </collision>
  </link>
  <link name="left_thumb_1">
    <inertial>
      <origin xyz="-0.026949999999999998 0.01478 0.07485" rpy="0 0 0" />
      <mass value="0.02407" />
      <inertia ixx="3.0396799999999998e-06" ixy="-1.2416e-07" ixz="8.392e-08" iyy="1.62329e-06" iyz="6.3491e-07" izz="2.25191e-06" />
    </inertial>
    <visual>
      <origin xyz="0 0 0" rpy="0 0 0" />
      <geometry>
        <mesh filename="meshes/left_hand/left_thumb_1.STL" />
      </geometry>
      <material name="">
        <color rgba="1 1 1 1" />
      </material>
    </visual>
    <collision>
      <origin xyz="0 0 0" rpy="0 0 0" />
      <geometry>
        <mesh filename="meshes/left_hand/left_thumb_1.STL" />
      </geometry>
    </collision>
  </link>
  <link name="left_thumb_2">
    <inertial>
      <origin xyz="-0.07454999999999999 0.03374 0.09742" rpy="0 0 0" />
      <mass value="0.01122" />
      <inertia ixx="1.11059e-06" ixy="-1.5098e-07" ixz="-3.9131000000000003e-07" iyy="1.5849400000000001e-06" iyz="-1.1285e-07" izz="1.18109e-06" />
    </inertial>
    <visual>
      <origin xyz="0 0 0" rpy="0 0 0" />
      <geometry>
        <mesh filename="meshes/left_hand/left_thumb_2.STL" />
      </geometry>
      <material name="">
        <color rgba="1 1 1 1" />
      </material>
    </visual>
    <collision>
      <origin xyz="0 0 0" rpy="0 0 0" />
      <geometry>
        <mesh filename="meshes/left_hand/left_thumb_2.STL" />
      </geometry>
    </collision>
  </link>
  <link name="left_thumb_3">
    <inertial>
      <origin xyz="-0.1022 0.04117 0.1138" rpy="0 0 0" />
      <mass value="0.0189" />
      <inertia ixx="1.32723e-06" ixy="-2.7513e-07" ixz="-6.8709e-07" iyy="2.26117e-06" iyz="-1.8584999999999999e-07" izz="2.02611e-06" />
    </inertial>
    <visual>
      <origin xyz="0 0 0" rpy="0 0 0" />
      <geometry>
        <mesh filename="meshes/left_hand/left_thumb_3.STL" />
      </geometry>
      <material name="">
        <color rgba="1 1 1 1" />
      </material>
    </visual>
    <collision>
      <origin xyz="0 0 0" rpy="0 0 0" />
      <geometry>
        <mesh filename="meshes/left_hand/left_thumb_3.STL" />
      </geometry>
    </collision>
  </link>
  <link name="left_thumb_force_sensor_2">
    <inertial>
      <origin xyz="-2.43332410831479E-05 5.44992472824302E-05 -0.00109137310434532" rpy="0 0 0" />
      <mass value="9.06121246347756E-05" />
      <inertia ixx="3.34748296277895E-10" ixy="3.77358736112153E-14" ixz="3.52273723202254E-13" iyy="3.35821649138781E-10" iyz="1.08964939417378E-12" izz="5.88578470286886E-10" />
    </inertial>
    <visual>
      <origin xyz="0 0 0" rpy="0 0 0" />
      <geometry>
        <mesh filename="meshes/left_hand/thumb_force_sensor_2.STL" />
      </geometry>
      <material name="">
        <color rgba="0.411764705882353 0.411764705882353 0.411764705882353 1" />
      </material>
    </visual>
    <collision>
      <origin xyz="0 0 0" rpy="0 0 0" />
      <geometry>
        <mesh filename="meshes/left_hand/thumb_force_sensor_2.STL" />
      </geometry>
    </collision>
  </link>
  <link name="left_thumb_4">
    <inertial>
      <origin xyz="-0.0163213563394194 0.00521928641987035 -0.00735104436106706" rpy="0 0 0" />
      <mass value="0.00878940797618241" />
      <inertia ixx="5.94897206401284E-07" ixy="2.54251361887254E-07" ixz="5.54085992162603E-11" iyy="7.79202349429445E-07" iyz="8.8965111980696E-11" izz="8.99824190088835E-07" />
    </inertial>
    <visual>
      <origin xyz="0 0 0" rpy="0 0 0" />
      <geometry>
        <mesh filename="meshes/left_hand/left_thumb_4.STL" />
      </geometry>
      <material name="">
        <color rgba="1 1 1 1" />
      </material>
    </visual>
    <collision>
      <origin xyz="0 0 0" rpy="0 0 0" />
      <geometry>
        <mesh filename="meshes/left_hand/left_thumb_4.STL" />
      </geometry>
    </collision>
  </link>
  <link name="left_thumb_force_sensor_3">
    <inertial>
      <origin xyz="1.23189696923445E-05 -0.000195538975680837 -0.000792005365136905" rpy="0 0 0" />
      <mass value="0.000276852313379015" />
      <inertia ixx="5.41173490291494E-09" ixy="-4.87700447907193E-13" ixz="-6.30024679424638E-13" iyy="2.55896079923591E-09" iyz="3.82351468308955E-11" izz="7.82764624814665E-09" />
    </inertial>
    <visual>
      <origin xyz="0 0 0" rpy="0 0 0" />
      <geometry>
        <mesh filename="meshes/left_hand/thumb_force_sensor_3.STL" />
      </geometry>
      <material name="">
        <color rgba="0.411764705882353 0.411764705882353 0.411764705882353 1" />
      </material>
    </visual>
    <collision>
      <origin xyz="0 0 0" rpy="0 0 0" />
      <geometry>
        <mesh filename="meshes/left_hand/thumb_force_sensor_3.STL" />
      </geometry>
    </collision>
  </link>
  <link name="left_thumb_force_sensor_4">
    <inertial>
      <origin xyz="8.78777579448042E-07 0.000270130629645191 -0.00100448285176212" rpy="0 0 0" />
      <mass value="5.0258739392813E-05" />
      <inertia ixx="8.13578898809676E-11" ixy="-2.55516319944346E-14" ixz="2.01520896001805E-14" iyy="1.70778531226233E-10" iyz="-3.77224272937059E-12" izz="2.11644262323665E-10" />
    </inertial>
    <visual>
      <origin xyz="0 0 0" rpy="0 0 0" />
      <geometry>
        <mesh filename="meshes/left_hand/thumb_force_sensor_4.STL" />
      </geometry>
      <material name="">
        <color rgba="0.411764705882353 0.411764705882353 0.411764705882353 1" />
      </material>
    </visual>
    <collision>
      <origin xyz="0 0 0" rpy="0 0 0" />
      <geometry>
        <mesh filename="meshes/left_hand/thumb_force_sensor_4.STL" />
      </geometry>
    </collision>
  </link>
  <link name="left_thumb_force_sensor_1">
    <inertial>
      <origin xyz="-1.66858232989106E-05 1.15630711571557E-05 -0.00107124647646149" rpy="0 0 0" />
      <mass value="0.000424630261957478" />
      <inertia ixx="9.01122065715071E-09" ixy="2.06673401320352E-14" ixz="2.31198472922275E-12" iyy="4.94557964402789E-09" iyz="1.1789230357668E-11" izz="1.35651342806704E-08" />
    </inertial>
    <visual>
      <origin xyz="0 0 0" rpy="0 0 0" />
      <geometry>
        <mesh filename="meshes/left_hand/thumb_force_sensor_1.STL" />
      </geometry>
      <material name="">
        <color rgba="0.411764705882353 0.411764705882353 0.411764705882353 1" />
      </material>
    </visual>
    <collision>
      <origin xyz="0 0 0" rpy="0 0 0" />
      <geometry>
        <mesh filename="meshes/left_hand/thumb_force_sensor_1.STL" />
      </geometry>
    </collision>
  </link>
  <link name="left_index_1">
    <inertial>
      <origin xyz="-0.032229999999999995 0.0012 0.16325" rpy="0 0 0" />
      <mass value="0.02456" />
      <inertia ixx="6.214600000000001e-06" ixy="-9.95e-09" ixz="-1.6013e-07" iyy="6.14166e-06" iyz="-2.5293000000000003e-07" izz="1.37478e-06" />
    </inertial>
    <visual>
      <origin xyz="0 0 0" rpy="0 0 0" />
      <geometry>
        <mesh filename="meshes/left_hand/left_index_1.STL" />
      </geometry>
      <material name="">
        <color rgba="1 1 1 1" />
      </material>
    </visual>
    <collision>
      <origin xyz="0 0 0" rpy="0 0 0" />
      <geometry>
        <mesh filename="meshes/left_hand/left_index_1.STL" />
      </geometry>
    </collision>
  </link>
  <link name="left_index_2">
    <inertial>
      <origin xyz="-0.03349 0.024120000000000003 0.19052000000000002" rpy="0 0 0" />
      <mass value="0.0124" />
      <inertia ixx="4.5689199999999996e-05" ixy="4.3484e-07" ixz="-4.3806e-07" iyy="2.01044e-05" iyz="2.1144599999999997e-05" izz="2.587996e-05" />
    </inertial>
    <visual>
      <origin xyz="0 0 0" rpy="0 0 0" />
      <geometry>
        <mesh filename="meshes/left_hand/left_index_2.STL" />
      </geometry>
      <material name="">
        <color rgba="1 1 1 1" />
      </material>
    </visual>
    <collision>
      <origin xyz="0 0 0" rpy="0 0 0" />
      <geometry>
        <mesh filename="meshes/left_hand/left_index_2.STL" />
      </geometry>
    </collision>
  </link>
  <link name="left_index_force_sensor_2">
    <inertial>
      <origin xyz="-3.92383751107728E-06 0.000206469730308023 -0.000722888601662641" rpy="0 0 0" />
      <mass value="0.000255748193489218" />
      <inertia ixx="4.7987768166369E-09" ixy="8.64189585169657E-11" ixz="1.5042180282212E-12" iyy="2.43957953886802E-09" iyz="-3.05164404848785E-11" izz="7.12568463704975E-09" />
    </inertial>
    <visual>
      <origin xyz="0 0 0" rpy="0 0 0" />
      <geometry>
        <mesh filename="meshes/left_hand/index_force_sensor_2.STL" />
      </geometry>
      <material name="">
        <color rgba="0.411764705882353 0.411764705882353 0.411764705882353 1" />
      </material>
    </visual>
    <collision>
      <origin xyz="0 0 0" rpy="0 0 0" />
      <geometry>
        <mesh filename="meshes/left_hand/index_force_sensor_2.STL" />
      </geometry>
    </collision>
  </link>
  <link name="left_index_force_sensor_3">
    <inertial>
      <origin xyz="2.48712002496876E-05 -0.000345284176963695 -0.00133798867886123" rpy="0 0 0" />
      <mass value="6.79653911304577E-05" />
      <inertia ixx="1.31976081706364E-10" ixy="-5.65097989610319E-12" ixz="-7.80109914730126E-13" iyy="2.53434470713008E-10" iyz="9.12174625129574E-12" izz="2.80536896961268E-10" />
    </inertial>
    <visual>
      <origin xyz="0 0 0" rpy="0 0 0" />
      <geometry>
        <mesh filename="meshes/left_hand/index_force_sensor_3.STL" />
      </geometry>
      <material name="">
        <color rgba="0.411764705882353 0.411764705882353 0.411764705882353 1" />
      </material>
    </visual>
    <collision>
      <origin xyz="0 0 0" rpy="0 0 0" />
      <geometry>
        <mesh filename="meshes/left_hand/index_force_sensor_3.STL" />
      </geometry>
    </collision>
  </link>
  <link name="left_index_force_sensor_1">
    <inertial>
      <origin xyz="-4.39980862962375E-06 0.000116492429592427 -0.000567426247601172" rpy="0 0 0" />
      <mass value="0.000202794475942537" />
      <inertia ixx="3.38062498899254E-09" ixy="5.06878020530947E-11" ixz="2.18895973514009E-13" iyy="1.96425205496783E-09" iyz="-5.52626408641069E-12" izz="5.28129594144099E-09" />
    </inertial>
    <visual>
      <origin xyz="0 0 0" rpy="0 0 0" />
      <geometry>
        <mesh filename="meshes/left_hand/index_force_sensor_1.STL" />
      </geometry>
      <material name="">
        <color rgba="0.411764705882353 0.411764705882353 0.411764705882353 1" />
      </material>
    </visual>
    <collision>
      <origin xyz="0 0 0" rpy="0 0 0" />
      <geometry>
        <mesh filename="meshes/left_hand/index_force_sensor_1.STL" />
      </geometry>
    </collision>
  </link>
  <link name="left_middle_1">
    <inertial>
      <origin xyz="-0.00983 -0.01618 0.16336" rpy="0 0 0" />
      <mass value="0.02456" />
      <inertia ixx="6.2201e-06" ixy="-3.08e-09" ixz="6.238000000000001e-08" iyy="6.08085e-06" iyz="5.9592e-07" izz="1.43272e-06" />
    </inertial>
    <visual>
      <origin xyz="0 0 0" rpy="0 0 0" />
      <geometry>
        <mesh filename="meshes/left_hand/left_middle_1.STL" />
      </geometry>
      <material name="">
        <color rgba="1 1 1 1" />
      </material>
    </visual>
    <collision>
      <origin xyz="0 0 0" rpy="0 0 0" />
      <geometry>
        <mesh filename="meshes/left_hand/left_middle_1.STL" />
      </geometry>
    </collision>
  </link>
  <link name="left_middle_2">
    <inertial>
      <origin xyz="-0.00928 -0.02389 0.21371" rpy="0 0 0" />
      <mass value="0.01299" />
      <inertia ixx="3.56712e-06" ixy="-7.719999999999999e-09" ixz="7.653e-08" iyy="3.63641e-06" iyz="3.398e-08" izz="3.7324e-07" />
    </inertial>
    <visual>
      <origin xyz="0 0 0" rpy="0 0 0" />
      <geometry>
        <mesh filename="meshes/left_hand/left_middle_2.STL" />
      </geometry>
      <material name="">
        <color rgba="1 1 1 1" />
      </material>
    </visual>
    <collision>
      <origin xyz="0 0 0" rpy="0 0 0" />
      <geometry>
        <mesh filename="meshes/left_hand/left_middle_2.STL" />
      </geometry>
    </collision>
  </link>
  <link name="left_middle_force_sensor_2">
    <inertial>
      <origin xyz="6.77351601335863E-07 2.94313228783732E-05 -0.000722425776846891" rpy="0 0 0" />
      <mass value="0.000262573593923131" />
      <inertia ixx="5.04148765936938E-09" ixy="1.87053180733119E-13" ixz="-1.9219839991417E-14" iyy="2.56777987860697E-09" iyz="3.47150599586582E-12" izz="7.49457837348363E-09" />
    </inertial>
    <visual>
      <origin xyz="0 0 0" rpy="0 0 0" />
      <geometry>
        <mesh filename="meshes/left_hand/middle_force_sensor_2.STL" />
      </geometry>
      <material name="">
        <color rgba="0.411764705882353 0.411764705882353 0.411764705882353 1" />
      </material>
    </visual>
    <collision>
      <origin xyz="0 0 0" rpy="0 0 0" />
      <geometry>
        <mesh filename="meshes/left_hand/middle_force_sensor_2.STL" />
      </geometry>
    </collision>
  </link>
  <link name="left_middle_force_sensor_3">
    <inertial>
      <origin xyz="-8.06940798625533E-08 -0.000365444698807449 -0.00127684015304248" rpy="0 0 0" />
      <mass value="6.64914272946033E-05" />
      <inertia ixx="1.27227716200634E-10" ixy="-8.96643675852232E-15" ixz="-8.77104798931421E-15" iyy="2.43691020872239E-10" iyz="7.61276541489738E-12" izz="2.75875028961867E-10" />
    </inertial>
    <visual>
      <origin xyz="0 0 0" rpy="0 0 0" />
      <geometry>
        <mesh filename="meshes/left_hand/middle_force_sensor_3.STL" />
      </geometry>
      <material name="">
        <color rgba="0.411764705882353 0.411764705882353 0.411764705882353 1" />
      </material>
    </visual>
    <collision>
      <origin xyz="0 0 0" rpy="0 0 0" />
      <geometry>
        <mesh filename="meshes/left_hand/middle_force_sensor_3.STL" />
      </geometry>
    </collision>
  </link>
  <link name="left_middle_force_sensor_1">
    <inertial>
      <origin xyz="-2.38805233448991E-07 0.00011657525419928 -0.00056742615707274" rpy="0 0 0" />
      <mass value="0.000202794522112888" />
      <inertia ixx="3.3824362190208E-09" ixy="2.84614711222524E-14" ixz="2.15581663153047E-14" iyy="1.96244127906411E-09" iyz="-5.53035966625832E-12" izz="5.28129636598898E-09" />
    </inertial>
    <visual>
      <origin xyz="0 0 0" rpy="0 0 0" />
      <geometry>
        <mesh filename="meshes/left_hand/middle_force_sensor_1.STL" />
      </geometry>
      <material name="">
        <color rgba="0.411764705882353 0.411764705882353 0.411764705882353 1" />
      </material>
    </visual>
    <collision>
      <origin xyz="0 0 0" rpy="0 0 0" />
      <geometry>
        <mesh filename="meshes/left_hand/middle_force_sensor_1.STL" />
      </geometry>
    </collision>
  </link>
  <link name="left_ring_1">
    <inertial>
      <origin xyz="0.011519999999999999 0.0010500000000000002 0.16331" rpy="0 0 0" />
      <mass value="0.02564" />
      <inertia ixx="6.281510000000001e-06" ixy="1.501e-08" ixz="2.6019e-07" iyy="6.20342e-06" iyz="-2.1600999999999999e-07" izz="1.4026700000000002e-06" />
    </inertial>
    <visual>
      <origin xyz="0 0 0" rpy="0 0 0" />
      <geometry>
        <mesh filename="meshes/left_hand/left_ring_1.STL" />
      </geometry>
      <material name="">
        <color rgba="1 1 1 1" />
      </material>
    </visual>
    <collision>
      <origin xyz="0 0 0" rpy="0 0 0" />
      <geometry>
        <mesh filename="meshes/left_hand/left_ring_1.STL" />
      </geometry>
    </collision>
  </link>
  <link name="left_ring_2">
    <inertial>
      <origin xyz="0.01267 0.024120000000000003 0.19037" rpy="0 0 0" />
      <mass value="0.0124" />
      <inertia ixx="4.56148e-05" ixy="-1.40969e-06" ixz="1.28852e-06" iyy="2.01044e-05" iyz="2.110204e-05" izz="2.595436e-05" />
    </inertial>
    <visual>
      <origin xyz="0 0 0" rpy="0 0 0" />
      <geometry>
        <mesh filename="meshes/left_hand/left_ring_2.STL" />
      </geometry>
      <material name="">
        <color rgba="1 1 1 1" />
      </material>
    </visual>
    <collision>
      <origin xyz="0 0 0" rpy="0 0 0" />
      <geometry>
        <mesh filename="meshes/left_hand/left_ring_2.STL" />
      </geometry>
    </collision>
  </link>
  <link name="left_ring_force_sensor_2">
    <inertial>
      <origin xyz="1.52347834277144E-05 0.00020594419620118 -0.000722888366235852" rpy="0 0 0" />
      <mass value="0.000255748190883603" />
      <inertia ixx="4.79445247032037E-09" ixy="-1.32856442479421E-10" ixz="-1.33138092961345E-12" iyy="2.4439035683218E-09" iyz="-3.05245098030189E-11" izz="7.12568419691734E-09" />
    </inertial>
    <visual>
      <origin xyz="0 0 0" rpy="0 0 0" />
      <geometry>
        <mesh filename="meshes/left_hand/ring_force_sensor_2.STL" />
      </geometry>
      <material name="">
        <color rgba="0.411764705882353 0.411764705882353 0.411764705882353 1" />
      </material>
    </visual>
    <collision>
      <origin xyz="0 0 0" rpy="0 0 0" />
      <geometry>
        <mesh filename="meshes/left_hand/ring_force_sensor_2.STL" />
      </geometry>
    </collision>
  </link>
  <link name="left_ring_force_sensor_3">
    <inertial>
      <origin xyz="-0.018987750288989 0.0666666818382249 0.0130188172795586" rpy="0 0 0" />
      <mass value="6.79657632016268E-05" />
      <inertia ixx="1.32111152752531E-10" ixy="7.12098038272761E-12" ixz="-8.55173235015504E-13" iyy="2.66757366976318E-10" iyz="1.63108112511305E-11" izz="2.67085052477174E-10" />
    </inertial>
    <visual>
      <origin xyz="0 0 0" rpy="0 0 0" />
      <geometry>
        <mesh filename="meshes/left_hand/ring_force_sensor_3.STL" />
      </geometry>
      <material name="">
        <color rgba="0.411764705882353 0.411764705882353 0.411764705882353 1" />
      </material>
    </visual>
    <collision>
      <origin xyz="0 0 0" rpy="0 0 0" />
      <geometry>
        <mesh filename="meshes/left_hand/ring_force_sensor_3.STL" />
      </geometry>
    </collision>
  </link>
  <link name="left_ring_force_sensor_1">
    <inertial>
      <origin xyz="6.00203522563292E-06 0.000116421389792051 -0.000567426346187727" rpy="0 0 0" />
      <mass value="0.000202794434376474" />
      <inertia ixx="3.37837011170993E-09" ixy="-7.58787529691318E-11" ixz="-2.74580424569917E-13" iyy="1.96650618264834E-09" iyz="-5.5239313808051E-12" izz="5.28129521919661E-09" />
    </inertial>
    <visual>
      <origin xyz="0 0 0" rpy="0 0 0" />
      <geometry>
        <mesh filename="meshes/left_hand/ring_force_sensor_1.STL" />
      </geometry>
      <material name="">
        <color rgba="0.411764705882353 0.411764705882353 0.411764705882353 1" />
      </material>
    </visual>
    <collision>
      <origin xyz="0 0 0" rpy="0 0 0" />
      <geometry>
        <mesh filename="meshes/left_hand/ring_force_sensor_1.STL" />
      </geometry>
    </collision>
  </link>
  <link name="left_little_1">
    <inertial>
      <origin xyz="0.03325 0.00124 0.15954" rpy="0 0 0" />
      <mass value="0.02456" />
      <inertia ixx="6.15542e-06" ixy="2.33e-08" ixz="5.1287e-07" iyy="6.1396099999999995e-06" iyz="-2.3261000000000002e-07" izz="1.41681e-06" />
    </inertial>
    <visual>
      <origin xyz="0 0 0" rpy="0 0 0" />
      <geometry>
        <mesh filename="meshes/left_hand/left_little_1.STL" />
      </geometry>
      <material name="">
        <color rgba="1 1 1 1" />
      </material>
    </visual>
    <collision>
      <origin xyz="0 0 0" rpy="0 0 0" />
      <geometry>
        <mesh filename="meshes/left_hand/left_little_1.STL" />
      </geometry>
    </collision>
  </link>
  <link name="left_little_2">
    <inertial>
      <origin xyz="0.03867 -0.02782 0.20235" rpy="0 0 0" />
      <mass value="0.009720000000000001" />
      <inertia ixx="1.6975399999999999e-06" ixy="-1.73e-09" ixz="1.8642e-07" iyy="1.7773499999999998e-06" iyz="-2.2100000000000003e-08" izz="2.8921e-07" />
    </inertial>
    <visual>
      <origin xyz="0 0 0" rpy="0 0 0" />
      <geometry>
        <mesh filename="meshes/left_hand/left_little_2.STL" />
      </geometry>
      <material name="">
        <color rgba="1 1 1 1" />
      </material>
    </visual>
    <collision>
      <origin xyz="0 0 0" rpy="0 0 0" />
      <geometry>
        <mesh filename="meshes/left_hand/left_little_2.STL" />
      </geometry>
    </collision>
  </link>
  <link name="left_little_force_sensor_2">
    <inertial>
      <origin xyz="0.0233410916816945 -0.0206057990619895 -0.0197632528662803" rpy="0 0 0" />
      <mass value="0.000280246748486092" />
      <inertia ixx="5.38916583855123E-09" ixy="5.7201609474287E-11" ixz="-2.9189249553302E-10" iyy="6.63241313034516E-09" iyz="-2.29244493996819E-09" izz="4.1372515955786E-09" />
    </inertial>
    <visual>
      <origin xyz="0 0 0" rpy="0 0 0" />
      <geometry>
        <mesh filename="meshes/left_hand/little_force_sensor_2.STL" />
      </geometry>
      <material name="">
        <color rgba="0.411764705882353 0.411764705882353 0.411764705882353 1" />
      </material>
    </visual>
    <collision>
      <origin xyz="0 0 0" rpy="0 0 0" />
      <geometry>
        <mesh filename="meshes/left_hand/little_force_sensor_2.STL" />
      </geometry>
    </collision>
  </link>
  <link name="left_little_force_sensor_3">
    <inertial>
      <origin xyz="-6.37037929382966E-05 -0.000437210532086563 -0.00112816117341033" rpy="0 0 0" />
      <mass value="6.10536670141782E-05" />
      <inertia ixx="1.11591596284104E-10" ixy="1.4892328691308E-11" ixz="1.18294492342107E-12" iyy="2.17206534672885E-10" iyz="8.0788357087695E-12" izz="2.52052305204087E-10" />
    </inertial>
    <visual>
      <origin xyz="0 0 0" rpy="0 0 0" />
      <geometry>
        <mesh filename="meshes/left_hand/little_force_sensor_3.STL" />
      </geometry>
      <material name="">
        <color rgba="0.411764705882353 0.411764705882353 0.411764705882353 1" />
      </material>
    </visual>
    <collision>
      <origin xyz="0 0 0" rpy="0 0 0" />
      <geometry>
        <mesh filename="meshes/left_hand/little_force_sensor_3.STL" />
      </geometry>
    </collision>
  </link>
  <link name="left_little_force_sensor_1">
    <inertial>
      <origin xyz="-0.00420187695671251 -0.0375159744513207 0.0151221430114555" rpy="0 0 0" />
      <mass value="0.000202794502264301" />
      <inertia ixx="3.37621922269687E-09" ixy="-5.57638291775712E-11" ixz="1.64362343088757E-10" iyy="2.88227222909127E-09" iyz="1.47325401248571E-09" izz="4.36768276890867E-09" />
    </inertial>
    <visual>
      <origin xyz="0 0 0" rpy="0 0 0" />
      <geometry>
        <mesh filename="meshes/left_hand/little_force_sensor_1.STL" />
      </geometry>
      <material name="">
        <color rgba="0.411764705882353 0.411764705882353 0.411764705882353 1" />
      </material>
    </visual>
    <collision>
      <origin xyz="0 0 0" rpy="0 0 0" />
      <geometry>
        <mesh filename="meshes/left_hand/little_force_sensor_1.STL" />
      </geometry>
    </collision>
  </link>
  <link name="left_palm_force_sensor">
    <inertial>
      <origin xyz="-0.000120093335186366 0.000717297413656857 -0.000692889069963995" rpy="0 0 0" />
      <mass value="0.00240886556268531" />
      <inertia ixx="1.79237847416289E-07" ixy="-3.62335251185339E-10" ixz="2.06838829647024E-10" iyy="5.01887324843794E-07" iyz="-4.23537057642119E-10" izz="6.80017237748917E-07" />
    </inertial>
    <visual>
      <origin xyz="0 0 0" rpy="0 0 0" />
      <geometry>
        <mesh filename="meshes/left_hand/palm_force_sensor.STL" />
      </geometry>
      <material name="">
        <color rgba="0.411764705882353 0.411764705882353 0.411764705882353 1" />
      </material>
    </visual>
    <collision>
      <origin xyz="0 0 0" rpy="0 0 0" />
      <geometry>
        <mesh filename="meshes/left_hand/palm_force_sensor.STL" />
      </geometry>
    </collision>
  </link>
  <joint name="left_thumb_1_joint" type="revolute">
    <origin xyz="0.0269 0.02101 0.0689" rpy="0 0 0" />
    <parent link="left_hand_base" />
    <child link="left_thumb_1" />
    <axis xyz="0 0 1" />
    <limit lower="0" upper="1.1641" effort="1" velocity="2" />
  </joint>
  <joint name="left_thumb_2_joint" type="revolute">
    <origin xyz="0.0073431 0.011232 0.0052" rpy="1.5708 0 -2.8798" />
    <parent link="left_thumb_1" />
    <child link="left_thumb_2" />
    <axis xyz="0 0 -1" />
    <limit lower="0" upper="0.5864" effort="2" velocity="1" />
  </joint>
  <joint name="left_thumb_3_joint" type="revolute">
    <origin xyz="-0.031403 0.021069 -0.001299" rpy="0 0 0" />
    <parent link="left_thumb_2" />
    <child link="left_thumb_3" />
    <axis xyz="0 0 -1" />
    <limit lower="0" upper="0.5" effort="1" velocity="2" />
    <mimic joint="left_thumb_2_joint" multiplier="0.8024" offset="0" />
  </joint>
  <joint name="left_thumb_force_sensor_2_joint" type="fixed">
    <origin xyz="-0.011771 0.01699 -0.0077514" rpy="1.8405 1.5705 -3.1416" />
    <parent link="left_thumb_3" />
    <child link="left_thumb_force_sensor_2" />
    <axis xyz="0 0 0" />
  </joint>
  <joint name="left_thumb_4_joint" type="revolute">
    <origin xyz="-0.0219027099524646 0.0128161397042487 -0.000300000000000231" rpy="0 0 0" />
    <parent link="left_thumb_3" />
    <child link="left_thumb_4" />
    <axis xyz="0 0 -1" />
    <limit lower="0" upper="3.14" effort="1" velocity="2" />
    <mimic joint="left_thumb_3_joint" multiplier="0.9487" offset="0" />
  </joint>
  <joint name="left_thumb_force_sensor_3_joint" type="fixed">
    <origin xyz="-0.014598 0.014721 -0.0073103" rpy="-0.18602 1.5708 0.84446" />
    <parent link="left_thumb_4" />
    <child link="left_thumb_force_sensor_3" />
    <axis xyz="0 0 0" />
  </joint>
  <joint name="left_thumb_force_sensor_4_joint" type="fixed">
    <origin xyz="-0.028987 0.017301 -0.0073513" rpy="2.0775 -1.5708 -3.14" />
    <parent link="left_thumb_4" />
    <child link="left_thumb_force_sensor_4" />
    <axis xyz="0 0 0" />
  </joint>
  <joint name="left_thumb_force_sensor_1_joint" type="fixed">
    <origin xyz="-0.0087121 0.026305 -0.0089605" rpy="1.2213 1.5708 2.44" />
    <parent link="left_thumb_2" />
    <child link="left_thumb_force_sensor_1" />
    <axis xyz="0 0 0" />
  </joint>
  <joint name="left_index_1_joint" type="revolute">
    <origin xyz="0.038679 0.00056467 0.1564" rpy="1.6057 0 1.5708" />
    <parent link="left_hand_base" />
    <child link="left_index_1" />
    <axis xyz="0 0 -1" />
    <limit lower="0" upper="1.4381" effort="1" velocity="2" />
  </joint>
  <joint name="left_index_2_joint" type="revolute">
    <origin xyz="0.0034259 0.032596 -0.00055" rpy="0 0 0" />
    <parent link="left_index_1" />
    <child link="left_index_2" />
    <axis xyz="0 0 -1" />
    <limit lower="0" upper="3.14" effort="1" velocity="2" />
    <mimic joint="left_index_1_joint" multiplier="1.0843" offset="0" />
  </joint>
  <joint name="left_index_force_sensor_2_joint" type="fixed">
    <origin xyz="0.0081655 0.037446 -0.0060795" rpy="-1.5708 1.5337 -1.9196" />
    <parent link="left_index_2" />
    <child link="left_index_force_sensor_2" />
    <axis xyz="0 0 0" />
  </joint>
  <joint name="left_index_force_sensor_3_joint" type="fixed">
    <origin xyz="0.0086237 0.052572 -0.0060954" rpy="-1.5708 1.5252 -0.87237" />
    <parent link="left_index_2" />
    <child link="left_index_force_sensor_3" />
    <axis xyz="0 0 0" />
  </joint>
  <joint name="left_index_force_sensor_1_joint" type="fixed">
    <origin xyz="0.012046 0.019649 -0.006651" rpy="-1.5708 1.5351 -1.3587" />
    <parent link="left_index_1" />
    <child link="left_index_force_sensor_1" />
    <axis xyz="0 0 0" />
  </joint>
  <joint name="left_middle_1_joint" type="revolute">
    <origin xyz="0.0171 0.00056467 0.157" rpy="1.5708 0 1.5708" />
    <parent link="left_hand_base" />
    <child link="left_middle_1" />
    <axis xyz="0 0 -1" />
    <limit lower="0" upper="1.4381" effort="1" velocity="2" />
  </joint>
  <joint name="left_middle_2_joint" type="revolute">
    <origin xyz="0.0034259 0.032596 -0.00055" rpy="0 0 0" />
    <parent link="left_middle_1" />
    <child link="left_middle_2" />
    <axis xyz="0 0 -1" />
    <limit lower="0" upper="3.14" effort="1" velocity="2" />
    <mimic joint="left_middle_1_joint" multiplier="1.0843" offset="0" />
  </joint>
  <joint name="left_middle_force_sensor_2_joint" type="fixed">
    <origin xyz="0.009086 0.040962 -0.0061003" rpy="-2.5053 1.5708 -2.8781" />
    <parent link="left_middle_2" />
    <child link="left_middle_force_sensor_2" />
    <axis xyz="0 0 0" />
  </joint>
  <joint name="left_middle_force_sensor_3_joint" type="fixed">
    <origin xyz="0 0.014323 -0.0048039" rpy="-1.0472 0 0" />
    <parent link="left_middle_force_sensor_2" />
    <child link="left_middle_force_sensor_3" />
    <axis xyz="0 0 0" />
  </joint>
  <joint name="left_middle_force_sensor_1_joint" type="fixed">
    <origin xyz="0.012046 0.019649 -0.006651" rpy="-2.4062 1.5708 -2.1941" />
    <parent link="left_middle_1" />
    <child link="left_middle_force_sensor_1" />
    <axis xyz="0 0 0" />
  </joint>
  <joint name="left_ring_1_joint" type="revolute">
    <origin xyz="-0.0045302 0.00056467 0.15683" rpy="1.5184 0 1.5708" />
    <parent link="left_hand_base" />
    <child link="left_ring_1" />
    <axis xyz="0 0 -1" />
    <limit lower="0" upper="1.4381" effort="1" velocity="2" />
  </joint>
  <joint name="left_ring_2_joint" type="revolute">
    <origin xyz="0.0034259 0.032596 -0.00055" rpy="0 0 0" />
    <parent link="left_ring_1" />
    <child link="left_ring_2" />
    <axis xyz="0 0 -1" />
    <limit lower="0" upper="3.14" effort="1" velocity="2" />
    <mimic joint="left_ring_1_joint" multiplier="1.0843" offset="0" />
  </joint>
  <joint name="left_ring_force_sensor_2_joint" type="fixed">
    <origin xyz="0.0081655 0.037446 -0.0060795" rpy="1.5708 1.5151 1.222" />
    <parent link="left_ring_2" />
    <child link="left_ring_force_sensor_2" />
    <axis xyz="0 0 0" />
  </joint>
  <joint name="left_ring_force_sensor_3_joint" type="fixed">
    <origin xyz="0.0086202 -0.01538 -0.028643" rpy="1.7654 1.5138 1.9769" />
    <parent link="left_ring_2" />
    <child link="left_ring_force_sensor_3" />
    <axis xyz="0 0 0" />
  </joint>
  <joint name="left_ring_force_sensor_1_joint" type="fixed">
    <origin xyz="0.012046 0.019649 -0.006651" rpy="1.5708 1.5172 1.7829" />
    <parent link="left_ring_1" />
    <child link="left_ring_force_sensor_1" />
    <axis xyz="0 0 0" />
  </joint>
  <joint name="left_little_1_joint" type="revolute">
    <origin xyz="-0.025916 0.00056467 0.15365" rpy="1.4661 0 1.5708" />
    <parent link="left_hand_base" />
    <child link="left_little_1" />
    <axis xyz="0 0 -1" />
    <limit lower="0" upper="1.4381" effort="1" velocity="2" />
  </joint>
  <joint name="left_little_2_joint" type="revolute">
    <origin xyz="0.0034259 0.032596 -0.00055" rpy="0 0 0" />
    <parent link="left_little_1" />
    <child link="left_little_2" />
    <axis xyz="0 0 -1" />
    <limit lower="0" upper="3.14" effort="1" velocity="2" />
    <mimic joint="left_little_1_joint" multiplier="1.0843" offset="0" />
  </joint>
  <joint name="left_little_force_sensor_2_joint" type="fixed">
    <origin xyz="0.0086237 0.053732 0.019972" rpy="1.2692 1.4573 1.9687" />
    <parent link="left_little_2" />
    <child link="left_little_force_sensor_2" />
    <axis xyz="0 0 0" />
  </joint>
  <joint name="left_little_force_sensor_3_joint" type="fixed">
    <origin xyz="0.0063973 0.042707 -0.0061154" rpy="1.5708 1.4336 2.2761" />
    <parent link="left_little_2" />
    <child link="left_little_force_sensor_3" />
    <axis xyz="0 0 0" />
  </joint>
  <joint name="left_little_force_sensor_1_joint" type="fixed">
    <origin xyz="0.0098773 0.060279 -0.0066672" rpy="1.5708 1.4597 1.2289" />
    <parent link="left_little_1" />
    <child link="left_little_force_sensor_1" />
    <axis xyz="0 0 0" />
  </joint>
  <joint name="left_palm_force_sensor_joint" type="fixed">
    <origin xyz="0.00036819 0.012296 0.1196" rpy="1.5708 0 3.1416" />
    <parent link="left_hand_base" />
    <child link="left_palm_force_sensor" />
    <axis xyz="0 0 0" />
  </joint>
  <link name="right_world" />
  <link name="right_hand_base">
    <inertial>
      <origin xyz="2e-05 -0.0024500000000000004 0.07793000000000001" rpy="0 0 0" />
      <mass value="0.6273500000000001" />
      <inertia ixx="0.0014968368000000001" ixy="-1.64393e-06" ixz="2.527401e-05" iyy="0.0017872599099999999" iyz="0.00012212543" izz="0.00071434062" />
    </inertial>
    <visual>
      <origin xyz="0 0 0" rpy="0 0 0" />
      <geometry>
        <mesh filename="meshes/right_hand/base_link.STL" />
      </geometry>
      <material name="">
        <color rgba="1 1 1 1" />
      </material>
    </visual>
    <collision>
      <origin xyz="0 0 0" rpy="0 0 0" />
      <geometry>
        <mesh filename="meshes/right_hand/base_link.STL" />
      </geometry>
    </collision>
  </link>
  <link name="right_palm_force_sensor">
    <inertial>
      <origin xyz="0.000120426871221421 0.000717269582936034 -0.0006928935004962" rpy="0 0 0" />
      <mass value="0.001" />
      <inertia ixx="1.792409847502E-07" ixy="3.5297874278755E-10" ixz="-2.06007907879908E-10" iyy="5.01925280756008E-07" iyz="-4.23310809567535E-10" izz="6.80058307355101E-07" />
    </inertial>
    <visual>
      <origin xyz="0 0 0" rpy="0 0 0" />
      <geometry>
        <mesh filename="meshes/right_hand/palm_force_sensor.STL" />
      </geometry>
      <material name="">
        <color rgba="0.411764705882353 0.411764705882353 0.411764705882353 1" />
      </material>
    </visual>
    <collision>
      <origin xyz="0 0 0" rpy="0 0 0" />
      <geometry>
        <mesh filename="meshes/right_hand/palm_force_sensor.STL" />
      </geometry>
    </collision>
  </link>
  <link name="right_thumb_1">
    <inertial>
      <origin xyz="-0.026949999999999998 0.01478 0.07485" rpy="0 0 0" />
      <mass value="0.02407" />
      <inertia ixx="3.0396799999999998e-06" ixy="1.2416e-07" ixz="-8.392e-08" iyy="1.62329e-06" iyz="6.3491e-07" izz="2.25191e-06" />
    </inertial>
    <visual>
      <origin xyz="0 0 0" rpy="0 0 0" />
      <geometry>
        <mesh filename="meshes/right_hand/right_thumb_1.STL" />
      </geometry>
      <material name="">
        <color rgba="1 1 1 1" />
      </material>
    </visual>
    <collision>
      <origin xyz="0 0 0" rpy="0 0 0" />
      <geometry>
        <mesh filename="meshes/right_hand/right_thumb_1.STL" />
      </geometry>
    </collision>
  </link>
  <link name="right_thumb_2">
    <inertial>
      <origin xyz="-0.046509999999999996 0.0245 0.08531" rpy="0 0 0" />
      <mass value="0.02426" />
      <inertia ixx="3.80486e-06" ixy="7.243600000000001e-07" ixz="1.19724e-06" iyy="6.95218e-06" iyz="-4.1933e-07" izz="5.52002e-06" />
    </inertial>
    <visual>
      <origin xyz="0 0 0" rpy="0 0 0" />
      <geometry>
        <mesh filename="meshes/right_hand/right_thumb_2.STL" />
      </geometry>
      <material name="">
        <color rgba="1 1 1 1" />
      </material>
    </visual>
    <collision>
      <origin xyz="0 0 0" rpy="0 0 0" />
      <geometry>
        <mesh filename="meshes/right_hand/right_thumb_2.STL" />
      </geometry>
    </collision>
  </link>
  <link name="right_thumb_3">
    <inertial>
      <origin xyz="-0.07454999999999999 0.03374 0.09742" rpy="0 0 0" />
      <mass value="0.01122" />
      <inertia ixx="1.11059e-06" ixy="1.5098e-07" ixz="3.9131000000000003e-07" iyy="1.5849400000000001e-06" iyz="-1.1285e-07" izz="1.18109e-06" />
    </inertial>
    <visual>
      <origin xyz="0 0 0" rpy="0 0 0" />
      <geometry>
        <mesh filename="meshes/right_hand/right_thumb_3.STL" />
      </geometry>
      <material name="">
        <color rgba="1 1 1 1" />
      </material>
    </visual>
    <collision>
      <origin xyz="0 0 0" rpy="0 0 0" />
      <geometry>
        <mesh filename="meshes/right_hand/right_thumb_3.STL" />
      </geometry>
    </collision>
  </link>
  <link name="right_thumb_force_sensor_2">
    <inertial>
      <origin xyz="2.43300294987259E-05 5.45016031029619E-05 -0.00109137669633625" rpy="0 0 0" />
      <mass value="0.001" />
      <inertia ixx="3.34747183285769E-10" ixy="-3.83618671521233E-14" ixz="-3.52155403886961E-13" iyy="3.3582079154486E-10" iyz="1.08928107999936E-12" izz="5.8857712310973E-10" />
    </inertial>
    <visual>
      <origin xyz="0 0 0" rpy="0 0 0" />
      <geometry>
        <mesh filename="meshes/right_hand/thumb_force_sensor_2.STL" />
      </geometry>
      <material name="">
        <color rgba="0.411764705882353 0.411764705882353 0.411764705882353 1" />
      </material>
    </visual>
    <collision>
      <origin xyz="0 0 0" rpy="0 0 0" />
      <geometry>
        <mesh filename="meshes/right_hand/thumb_force_sensor_2.STL" />
      </geometry>
    </collision>
  </link>
  <link name="right_thumb_4">
    <inertial>
      <origin xyz="-0.1022 0.04117 0.1138" rpy="0 0 0" />
      <mass value="0.0189" />
      <inertia ixx="1.32723e-06" ixy="2.7513e-07" ixz="6.8709e-07" iyy="2.26117e-06" iyz="-1.8584999999999999e-07" izz="2.02611e-06" />
    </inertial>
    <visual>
      <origin xyz="0 0 0" rpy="0 0 0" />
      <geometry>
        <mesh filename="meshes/right_hand/right_thumb_4.STL" />
      </geometry>
      <material name="">
        <color rgba="1 1 1 1" />
      </material>
    </visual>
    <collision>
      <origin xyz="0 0 0" rpy="0 0 0" />
      <geometry>
        <mesh filename="meshes/right_hand/right_thumb_4.STL" />
      </geometry>
    </collision>
  </link>
  <link name="right_thumb_force_sensor_3">
    <inertial>
      <origin xyz="-1.23775059738263E-05 -0.000195169652742258 -0.000791740559016839" rpy="0 0 0" />
      <mass value="0.001" />
      <inertia ixx="5.41310691342173E-09" ixy="6.87296172207439E-13" ixz="6.30644149217552E-13" iyy="2.55911790350329E-09" iyz="3.82480948255569E-11" izz="7.82908815507693E-09" />
    </inertial>
    <visual>
      <origin xyz="0 0 0" rpy="0 0 0" />
      <geometry>
        <mesh filename="meshes/right_hand/thumb_force_sensor_3.STL" />
      </geometry>
      <material name="">
        <color rgba="0.411764705882353 0.411764705882353 0.411764705882353 1" />
      </material>
    </visual>
    <collision>
      <origin xyz="0 0 0" rpy="0 0 0" />
      <geometry>
        <mesh filename="meshes/right_hand/thumb_force_sensor_3.STL" />
      </geometry>
    </collision>
  </link>
  <link name="right_thumb_force_sensor_4">
    <inertial>
      <origin xyz="-7.92360954363081E-07 0.000270176676441192 -0.00100449430451509" rpy="0 0 0" />
      <mass value="0.001" />
      <inertia ixx="8.13571079919818E-11" ixy="2.58693510294188E-14" ixz="-1.96984280101514E-14" iyy="1.7077491736553E-10" iyz="-3.77214180289288E-12" izz="2.11640709143909E-10" />
    </inertial>
    <visual>
      <origin xyz="0 0 0" rpy="0 0 0" />
      <geometry>
        <mesh filename="meshes/right_hand/thumb_force_sensor_4.STL" />
      </geometry>
      <material name="">
        <color rgba="0.411764705882353 0.411764705882353 0.411764705882353 1" />
      </material>
    </visual>
    <collision>
      <origin xyz="0 0 0" rpy="0 0 0" />
      <geometry>
        <mesh filename="meshes/right_hand/thumb_force_sensor_4.STL" />
      </geometry>
    </collision>
  </link>
  <link name="right_thumb_force_sensor_1">
    <inertial>
      <origin xyz="1.67085981274823E-05 1.15915239991271E-05 -0.00107125254163185" rpy="0 0 0" />
      <mass value="0.001" />
      <inertia ixx="9.01126285102489E-09" ixy="-2.19183765993572E-15" ixz="-2.32024611820209E-12" iyy="4.94554439784859E-09" iyz="1.17775921788887E-11" izz="1.35651458253969E-08" />
    </inertial>
    <visual>
      <origin xyz="0 0 0" rpy="0 0 0" />
      <geometry>
        <mesh filename="meshes/right_hand/thumb_force_sensor_1.STL" />
      </geometry>
      <material name="">
        <color rgba="0.411764705882353 0.411764705882353 0.411764705882353 1" />
      </material>
    </visual>
    <collision>
      <origin xyz="0 0 0" rpy="0 0 0" />
      <geometry>
        <mesh filename="meshes/right_hand/thumb_force_sensor_1.STL" />
      </geometry>
    </collision>
  </link>
  <link name="right_index_1">
    <inertial>
      <origin xyz="-0.032229999999999995 0.0012 0.16325" rpy="0 0 0" />
      <mass value="0.02456" />
      <inertia ixx="6.214600000000001e-06" ixy="9.95e-09" ixz="1.6013e-07" iyy="6.14166e-06" iyz="-2.5293000000000003e-07" izz="1.37478e-06" />
    </inertial>
    <visual>
      <origin xyz="0 0 0" rpy="0 0 0" />
      <geometry>
        <mesh filename="meshes/right_hand/right_index_1.STL" />
      </geometry>
      <material name="">
        <color rgba="1 1 1 1" />
      </material>
    </visual>
    <collision>
      <origin xyz="0 0 0" rpy="0 0 0" />
      <geometry>
        <mesh filename="meshes/right_hand/right_index_1.STL" />
      </geometry>
    </collision>
  </link>
  <link name="right_index_2">
    <inertial>
      <origin xyz="-0.03349 0.024120000000000003 0.19052000000000002" rpy="0 0 0" />
      <mass value="0.0124" />
      <inertia ixx="4.5689199999999996e-05" ixy="-4.3484e-07" ixz="4.3806e-07" iyy="2.01044e-05" iyz="2.1144599999999997e-05" izz="2.587996e-05" />
    </inertial>
    <visual>
      <origin xyz="0 0 0" rpy="0 0 0" />
      <geometry>
        <mesh filename="meshes/right_hand/right_index_2.STL" />
      </geometry>
      <material name="">
        <color rgba="1 1 1 1" />
      </material>
    </visual>
    <collision>
      <origin xyz="0 0 0" rpy="0 0 0" />
      <geometry>
        <mesh filename="meshes/right_hand/right_index_2.STL" />
      </geometry>
    </collision>
  </link>
  <link name="right_index_force_sensor_2">
    <inertial>
      <origin xyz="3.91105790090857E-06 0.000206428506730846 -0.000722888656592813" rpy="0 0 0" />
      <mass value="0.001" />
      <inertia ixx="4.79878645065383E-09" ixy="-8.64076408119868E-11" ixz="-1.50330115198978E-12" iyy="2.43958893457374E-09" iyz="-3.05132448820234E-11" izz="7.12570334555721E-09" />
    </inertial>
    <visual>
      <origin xyz="0 0 0" rpy="0 0 0" />
      <geometry>
        <mesh filename="meshes/right_hand/index_force_sensor_2.STL" />
      </geometry>
      <material name="">
        <color rgba="0.411764705882353 0.411764705882353 0.411764705882353 1" />
      </material>
    </visual>
    <collision>
      <origin xyz="0 0 0" rpy="0 0 0" />
      <geometry>
        <mesh filename="meshes/right_hand/index_force_sensor_2.STL" />
      </geometry>
    </collision>
  </link>
  <link name="right_index_force_sensor_3">
    <inertial>
      <origin xyz="-2.48722057788475E-05 -0.000345285689256153 -0.00133800038179009" rpy="0 0 0" />
      <mass value="0.001" />
      <inertia ixx="1.31974821284448E-10" ixy="5.65060068039544E-12" ixz="7.79117122469869E-13" iyy="2.53430134807533E-10" iyz="9.12198063131294E-12" izz="2.8053351791299E-10" />
    </inertial>
    <visual>
      <origin xyz="0 0 0" rpy="0 0 0" />
      <geometry>
        <mesh filename="meshes/right_hand/index_force_sensor_3.STL" />
      </geometry>
      <material name="">
        <color rgba="0.411764705882353 0.411764705882353 0.411764705882353 1" />
      </material>
    </visual>
    <collision>
      <origin xyz="0 0 0" rpy="0 0 0" />
      <geometry>
        <mesh filename="meshes/right_hand/index_force_sensor_3.STL" />
      </geometry>
    </collision>
  </link>
  <link name="right_index_force_sensor_1">
    <inertial>
      <origin xyz="4.50639917342482E-06 0.000116571661332499 -0.000567443126962358" rpy="0 0 0" />
      <mass value="0.001" />
      <inertia ixx="3.38028798502951E-09" ixy="-5.04640338896759E-11" ixz="-2.15701714440087E-13" iyy="1.96412698995832E-09" iyz="-5.48195334354584E-12" izz="5.28079732652296E-09" />
    </inertial>
    <visual>
      <origin xyz="0 0 0" rpy="0 0 0" />
      <geometry>
        <mesh filename="meshes/right_hand/index_force_sensor_1.STL" />
      </geometry>
      <material name="">
        <color rgba="0.411764705882353 0.411764705882353 0.411764705882353 1" />
      </material>
    </visual>
    <collision>
      <origin xyz="0 0 0" rpy="0 0 0" />
      <geometry>
        <mesh filename="meshes/right_hand/index_force_sensor_1.STL" />
      </geometry>
    </collision>
  </link>
  <link name="right_middle_1">
    <inertial>
      <origin xyz="-0.00983 -0.01618 0.16336" rpy="0 0 0" />
      <mass value="0.02456" />
      <inertia ixx="6.2201e-06" ixy="3.08e-09" ixz="-6.238000000000001e-08" iyy="6.08085e-06" iyz="5.9592e-07" izz="1.43272e-06" />
    </inertial>
    <visual>
      <origin xyz="0 0 0" rpy="0 0 0" />
      <geometry>
        <mesh filename="meshes/right_hand/right_middle_1.STL" />
      </geometry>
      <material name="">
        <color rgba="1 1 1 1" />
      </material>
    </visual>
    <collision>
      <origin xyz="0 0 0" rpy="0 0 0" />
      <geometry>
        <mesh filename="meshes/right_hand/right_middle_1.STL" />
      </geometry>
    </collision>
  </link>
  <link name="right_middle_2">
    <inertial>
      <origin xyz="-0.00928 -0.02389 0.21371" rpy="0 0 0" />
      <mass value="0.01299" />
      <inertia ixx="3.56712e-06" ixy="7.719999999999999e-09" ixz="-7.653e-08" iyy="3.63641e-06" iyz="3.398e-08" izz="3.7324e-07" />
    </inertial>
    <visual>
      <origin xyz="0 0 0" rpy="0 0 0" />
      <geometry>
        <mesh filename="meshes/right_hand/right_middle_2.STL" />
      </geometry>
      <material name="">
        <color rgba="1 1 1 1" />
      </material>
    </visual>
    <collision>
      <origin xyz="0 0 0" rpy="0 0 0" />
      <geometry>
        <mesh filename="meshes/right_hand/right_middle_2.STL" />
      </geometry>
    </collision>
  </link>
  <link name="right_middle_force_sensor_2">
    <inertial>
      <origin xyz="-3.55652627983399E-07 2.88666331397097E-05 -0.000722235489778011" rpy="0 0 0" />
      <mass value="0.001" />
      <inertia ixx="5.0422606271269E-09" ixy="3.96627458520336E-13" ixz="-3.26041478715661E-14" iyy="2.56807850635636E-09" iyz="3.53736208701199E-12" izz="7.49563436241948E-09" />
    </inertial>
    <visual>
      <origin xyz="0 0 0" rpy="0 0 0" />
      <geometry>
        <mesh filename="meshes/right_hand/middle_force_sensor_2.STL" />
      </geometry>
      <material name="">
        <color rgba="0.411764705882353 0.411764705882353 0.411764705882353 1" />
      </material>
    </visual>
    <collision>
      <origin xyz="0 0 0" rpy="0 0 0" />
      <geometry>
        <mesh filename="meshes/right_hand/middle_force_sensor_2.STL" />
      </geometry>
    </collision>
  </link>
  <link name="right_middle_force_sensor_3">
    <inertial>
      <origin xyz="6.04731043574169E-08 -0.00036544534557964 -0.00127683945630336" rpy="0 0 0" />
      <mass value="0.001" />
      <inertia ixx="1.27227764572837E-10" ixy="1.00476590749141E-14" ixz="8.57880628295176E-15" iyy="2.43691164484046E-10" iyz="7.61272996067342E-12" izz="2.7587517056304E-10" />
    </inertial>
    <visual>
      <origin xyz="0 0 0" rpy="0 0 0" />
      <geometry>
        <mesh filename="meshes/right_hand/middle_force_sensor_3.STL" />
      </geometry>
      <material name="">
        <color rgba="0.411764705882353 0.411764705882353 0.411764705882353 1" />
      </material>
    </visual>
    <collision>
      <origin xyz="0 0 0" rpy="0 0 0" />
      <geometry>
        <mesh filename="meshes/right_hand/middle_force_sensor_3.STL" />
      </geometry>
    </collision>
  </link>
  <link name="right_middle_force_sensor_1">
    <inertial>
      <origin xyz="3.42843697213185E-07 0.000116657509605197 -0.000567442695803486" rpy="0 0 0" />
      <mass value="0.001" />
      <inertia ixx="3.38208410519618E-09" ixy="1.8756957436983E-13" ixz="-1.99647221364603E-14" iyy="1.96233204624223E-09" iyz="-5.48580562274466E-12" izz="5.2807983995112E-09" />
    </inertial>
    <visual>
      <origin xyz="0 0 0" rpy="0 0 0" />
      <geometry>
        <mesh filename="meshes/right_hand/middle_force_sensor_1.STL" />
      </geometry>
      <material name="">
        <color rgba="0.411764705882353 0.411764705882353 0.411764705882353 1" />
      </material>
    </visual>
    <collision>
      <origin xyz="0 0 0" rpy="0 0 0" />
      <geometry>
        <mesh filename="meshes/right_hand/middle_force_sensor_1.STL" />
      </geometry>
    </collision>
  </link>
  <link name="right_ring_1">
    <inertial>
      <origin xyz="0.011519999999999999 0.0010500000000000002 0.16331" rpy="0 0 0" />
      <mass value="0.02564" />
      <inertia ixx="6.281510000000001e-06" ixy="-1.501e-08" ixz="-2.6019e-07" iyy="6.20342e-06" iyz="-2.1600999999999999e-07" izz="1.4026700000000002e-06" />
    </inertial>
    <visual>
      <origin xyz="0 0 0" rpy="0 0 0" />
      <geometry>
        <mesh filename="meshes/right_hand/right_ring_1.STL" />
      </geometry>
      <material name="">
        <color rgba="1 1 1 1" />
      </material>
    </visual>
    <collision>
      <origin xyz="0 0 0" rpy="0 0 0" />
      <geometry>
        <mesh filename="meshes/right_hand/right_ring_1.STL" />
      </geometry>
    </collision>
  </link>
  <link name="right_ring_2">
    <inertial>
      <origin xyz="0.01267 0.024120000000000003 0.19037" rpy="0 0 0" />
      <mass value="0.0124" />
      <inertia ixx="4.56148e-05" ixy="1.40969e-06" ixz="-1.28852e-06" iyy="2.01044e-05" iyz="2.110204e-05" izz="2.595436e-05" />
    </inertial>
    <visual>
      <origin xyz="0 0 0" rpy="0 0 0" />
      <geometry>
        <mesh filename="meshes/right_hand/right_ring_2.STL" />
      </geometry>
      <material name="">
        <color rgba="1 1 1 1" />
      </material>
    </visual>
    <collision>
      <origin xyz="0 0 0" rpy="0 0 0" />
      <geometry>
        <mesh filename="meshes/right_hand/right_ring_2.STL" />
      </geometry>
    </collision>
  </link>
  <link name="right_ring_force_sensor_2">
    <inertial>
      <origin xyz="-1.52436836100122E-05 0.000205901966578506 -0.000722888420897932" rpy="0 0 0" />
      <mass value="0.001" />
      <inertia ixx="4.79446001367797E-09" ixy="1.32867587230544E-10" ixz="1.3319969497832E-12" iyy="2.44391505492957E-09" iyz="-3.05212434039785E-11" izz="7.12570290551646E-09" />
    </inertial>
    <visual>
      <origin xyz="0 0 0" rpy="0 0 0" />
      <geometry>
        <mesh filename="meshes/right_hand/ring_force_sensor_2.STL" />
      </geometry>
      <material name="">
        <color rgba="0.411764705882353 0.411764705882353 0.411764705882353 1" />
      </material>
    </visual>
    <collision>
      <origin xyz="0 0 0" rpy="0 0 0" />
      <geometry>
        <mesh filename="meshes/right_hand/ring_force_sensor_2.STL" />
      </geometry>
    </collision>
  </link>
  <link name="right_ring_force_sensor_3">
    <inertial>
      <origin xyz="1.45480090249107E-05 -0.000345868489067203 -0.00133799622683203" rpy="0 0 0" />
      <mass value="0.001" />
      <inertia ixx="1.32268380918037E-10" ixy="-8.21005557691383E-12" ixz="-2.63863504125309E-13" iyy="2.53139740379503E-10" iyz="9.1510626727994E-12" izz="2.80536239837899E-10" />
    </inertial>
    <visual>
      <origin xyz="0 0 0" rpy="0 0 0" />
      <geometry>
        <mesh filename="meshes/right_hand/ring_force_sensor_3.STL" />
      </geometry>
      <material name="">
        <color rgba="0.411764705882353 0.411764705882353 0.411764705882353 1" />
      </material>
    </visual>
    <collision>
      <origin xyz="0 0 0" rpy="0 0 0" />
      <geometry>
        <mesh filename="meshes/right_hand/ring_force_sensor_3.STL" />
      </geometry>
    </collision>
  </link>
  <link name="right_ring_force_sensor_1">
    <inertial>
      <origin xyz="-5.90327958142033E-06 0.000116509445804644 -0.000567443259521572" rpy="0 0 0" />
      <mass value="0.001" />
      <inertia ixx="3.37799540185096E-09" ixy="7.60796091703617E-11" ixz="2.73854397843076E-13" iyy="1.96641957767428E-09" iyz="-5.47947431188363E-12" izz="5.28079735826682E-09" />
    </inertial>
    <visual>
      <origin xyz="0 0 0" rpy="0 0 0" />
      <geometry>
        <mesh filename="meshes/right_hand/ring_force_sensor_1.STL" />
      </geometry>
      <material name="">
        <color rgba="0.411764705882353 0.411764705882353 0.411764705882353 1" />
      </material>
    </visual>
    <collision>
      <origin xyz="0 0 0" rpy="0 0 0" />
      <geometry>
        <mesh filename="meshes/right_hand/ring_force_sensor_1.STL" />
      </geometry>
    </collision>
  </link>
  <link name="right_little_1">
    <inertial>
      <origin xyz="0.03325 0.00124 0.15954" rpy="0 0 0" />
      <mass value="0.02456" />
      <inertia ixx="6.15542e-06" ixy="-2.33e-08" ixz="-5.1287e-07" iyy="6.1396099999999995e-06" iyz="-2.3261000000000002e-07" izz="1.41681e-06" />
    </inertial>
    <visual>
      <origin xyz="0 0 0" rpy="0 0 0" />
      <geometry>
        <mesh filename="meshes/right_hand/right_little_1.STL" />
      </geometry>
      <material name="">
        <color rgba="1 1 1 1" />
      </material>
    </visual>
    <collision>
      <origin xyz="0 0 0" rpy="0 0 0" />
      <geometry>
        <mesh filename="meshes/right_hand/right_little_1.STL" />
      </geometry>
    </collision>
  </link>
  <link name="right_little_2">
    <inertial>
      <origin xyz="0.03867 -0.02782 0.20235" rpy="0 0 0" />
      <mass value="0.009720000000000001" />
      <inertia ixx="1.6975399999999999e-06" ixy="1.73e-09" ixz="-1.8642e-07" iyy="1.7773499999999998e-06" iyz="-2.2100000000000003e-08" izz="2.8921e-07" />
    </inertial>
    <visual>
      <origin xyz="0 0 0" rpy="0 0 0" />
      <geometry>
        <mesh filename="meshes/right_hand/right_little_2.STL" />
      </geometry>
      <material name="">
        <color rgba="1 1 1 1" />
      </material>
    </visual>
    <collision>
      <origin xyz="0 0 0" rpy="0 0 0" />
      <geometry>
        <mesh filename="meshes/right_hand/right_little_2.STL" />
      </geometry>
    </collision>
  </link>
  <link name="right_little_force_sensor_2">
    <inertial>
      <origin xyz="1.83850807690782E-05 -0.000118792499944516 -0.00077353663965421" rpy="0 0 0" />
      <mass value="0.001" />
      <inertia ixx="5.36105565367509E-09" ixy="2.9087102385881E-10" ixz="-4.23704440233772E-12" iyy="2.78924633862048E-09" iyz="3.60734545957644E-11" izz="8.01055296833179E-09" />
    </inertial>
    <visual>
      <origin xyz="0 0 0" rpy="0 0 0" />
      <geometry>
        <mesh filename="meshes/right_hand/little_force_sensor_2.STL" />
      </geometry>
      <material name="">
        <color rgba="0.411764705882353 0.411764705882353 0.411764705882353 1" />
      </material>
    </visual>
    <collision>
      <origin xyz="0 0 0" rpy="0 0 0" />
      <geometry>
        <mesh filename="meshes/right_hand/little_force_sensor_2.STL" />
      </geometry>
    </collision>
  </link>
  <link name="right_little_force_sensor_3">
    <inertial>
      <origin xyz="6.36863053951123E-05 -0.000437236774208316 -0.00112814037373121" rpy="0 0 0" />
      <mass value="0.001" />
      <inertia ixx="1.11592356002466E-10" ixy="-1.48925479775264E-11" ixz="-1.18387481927136E-12" iyy="2.17209112811676E-10" iyz="8.07880135891967E-12" izz="2.52055535156648E-10" />
    </inertial>
    <visual>
      <origin xyz="0 0 0" rpy="0 0 0" />
      <geometry>
        <mesh filename="meshes/right_hand/little_force_sensor_3.STL" />
      </geometry>
      <material name="">
        <color rgba="0.411764705882353 0.411764705882353 0.411764705882353 1" />
      </material>
    </visual>
    <collision>
      <origin xyz="0 0 0" rpy="0 0 0" />
      <geometry>
        <mesh filename="meshes/right_hand/little_force_sensor_3.STL" />
      </geometry>
    </collision>
  </link>
  <link name="right_little_force_sensor_1">
    <inertial>
      <origin xyz="-1.2130080955873E-05 0.000116026903212899 -0.00056744299424992" rpy="0 0 0" />
      <mass value="0.001" />
      <inertia ixx="3.3658199564233E-09" ixy="1.51080971417152E-10" ixz="5.66657100478518E-13" iyy="1.97859528185445E-09" iyz="-5.45672948532754E-12" izz="5.28079755559196E-09" />
    </inertial>
    <visual>
      <origin xyz="0 0 0" rpy="0 0 0" />
      <geometry>
        <mesh filename="meshes/right_hand/little_force_sensor_1.STL" />
      </geometry>
      <material name="">
        <color rgba="0.411764705882353 0.411764705882353 0.411764705882353 1" />
      </material>
    </visual>
    <collision>
      <origin xyz="0 0 0" rpy="0 0 0" />
      <geometry>
        <mesh filename="meshes/right_hand/little_force_sensor_1.STL" />
      </geometry>
    </collision>
  </link>
  <joint name="right_base_joint" type="fixed">
    <parent link="right_world" />
    <child link="right_hand_base" />
  </joint>
  <joint name="right_palm_force_sensor_joint" type="fixed">
    <origin xyz="-0.00036819 0.012296 0.1196" rpy="1.5708 0 -3.1416" />
    <parent link="right_hand_base" />
    <child link="right_palm_force_sensor" />
    <axis xyz="0 0 0" />
  </joint>
  <joint name="right_thumb_1_joint" type="revolute">
    <origin xyz="-0.0269 0.02101 0.0689" rpy="0 0 0" />
    <parent link="right_hand_base" />
    <child link="right_thumb_1" />
    <axis xyz="0 0 -1" />
    <limit lower="0" upper="1.1641" effort="10" velocity="1" />
  </joint>
  <joint name="right_thumb_2_joint" type="revolute">
    <origin xyz="-0.0079252 0.0090599 0.0052" rpy="1.5708 0 2.8798" />
    <parent link="right_thumb_1" />
    <child link="right_thumb_2" />
    <axis xyz="0 0 1" />
    <limit lower="0" upper="0.5864" effort="10" velocity="1" />
  </joint>
  <joint name="right_thumb_3_joint" type="revolute">
    <origin xyz="0.031403 0.021069 0.00095" rpy="0 0 0" />
    <parent link="right_thumb_2" />
    <child link="right_thumb_3" />
    <axis xyz="0 0 1" />
    <limit lower="0" upper="0.5" effort="10" velocity="1" />
    <mimic joint="right_thumb_2_joint" multiplier="0.8024" offset="0" />
  </joint>
  <joint name="right_thumb_force_sensor_2_joint" type="fixed">
    <origin xyz="0.011771 0.01699 -0.0077514" rpy="1.8405 -1.5705 3.1416" />
    <parent link="right_thumb_3" />
    <child link="right_thumb_force_sensor_2" />
    <axis xyz="0 0 0" />
  </joint>
  <joint name="right_thumb_4_joint" type="revolute">
    <origin xyz="0.021903 0.012816 -0.0003" rpy="0 0 0" />
    <parent link="right_thumb_3" />
    <child link="right_thumb_4" />
    <axis xyz="0 0 1" />
    <limit lower="0" upper="3.14" effort="10" velocity="1" />
    <mimic joint="right_thumb_3_joint" multiplier="0.9487" offset="0" />
  </joint>
  <joint name="right_thumb_force_sensor_3_joint" type="fixed">
    <origin xyz="0.014598 0.01472 -0.0073103" rpy="-0.20892 -1.5708 -0.81953" />
    <parent link="right_thumb_4" />
    <child link="right_thumb_force_sensor_3" />
    <axis xyz="0 0 0" />
  </joint>
  <joint name="right_thumb_force_sensor_4_joint" type="fixed">
    <origin xyz="0.028987 0.017301 -0.0073512" rpy="1.6795 1.5708 2.7448" />
    <parent link="right_thumb_4" />
    <child link="right_thumb_force_sensor_4" />
    <axis xyz="0 0 0" />
  </joint>
  <joint name="right_thumb_force_sensor_1_joint" type="fixed">
    <origin xyz="0.0087121 0.026305 -0.0067115" rpy="-1.5728 -1.5708 0.35156" />
    <parent link="right_thumb_2" />
    <child link="right_thumb_force_sensor_1" />
    <axis xyz="0 0 0" />
  </joint>
  <joint name="right_index_1_joint" type="revolute">
    <origin xyz="-0.038679 0.00056467 0.1564" rpy="1.6057 0 -1.5708" />
    <parent link="right_hand_base" />
    <child link="right_index_1" />
    <axis xyz="0 0 1" />
    <limit lower="0" upper="1.4381" effort="10" velocity="1" />
  </joint>
  <joint name="right_index_2_joint" type="revolute">
    <origin xyz="-0.0034259 0.032596 -0.00055" rpy="0 0 0" />
    <parent link="right_index_1" />
    <child link="right_index_2" />
    <axis xyz="0 0 1" />
    <limit lower="0" upper="3.14" effort="10" velocity="1" />
    <mimic joint="right_index_1_joint" multiplier="1.0843" offset="0" />
  </joint>
  <joint name="right_index_force_sensor_2_joint" type="fixed">
    <origin xyz="-0.0081655 0.037446 -0.0060795" rpy="-1.5708 -1.5337 1.9196" />
    <parent link="right_index_2" />
    <child link="right_index_force_sensor_2" />
    <axis xyz="0 0 0" />
  </joint>
  <joint name="right_index_force_sensor_3_joint" type="fixed">
    <origin xyz="-0.0086237 0.052572 -0.0060954" rpy="-1.5708 -1.5252 0.87237" />
    <parent link="right_index_2" />
    <child link="right_index_force_sensor_3" />
    <axis xyz="0 0 0" />
  </joint>
  <joint name="right_index_force_sensor_1_joint" type="fixed">
    <origin xyz="-0.012046 0.019649 -0.006651" rpy="-1.5708 -1.5351 1.3587" />
    <parent link="right_index_1" />
    <child link="right_index_force_sensor_1" />
    <axis xyz="0 0 0" />
  </joint>
  <joint name="right_middle_1_joint" type="revolute">
    <origin xyz="-0.0171 0.00056467 0.157" rpy="1.5708 0 -1.5708" />
    <parent link="right_hand_base" />
    <child link="right_middle_1" />
    <axis xyz="0 0 1" />
    <limit lower="0" upper="1.4381" effort="10" velocity="1" />
  </joint>
  <joint name="right_middle_2_joint" type="revolute">
    <origin xyz="-0.0034259 0.032596 -0.00055" rpy="0 0 0" />
    <parent link="right_middle_1" />
    <child link="right_middle_2" />
    <axis xyz="0 0 1" />
    <limit lower="0" upper="3.14" effort="10" velocity="1" />
    <mimic joint="right_middle_1_joint" multiplier="1.0843" offset="0" />
  </joint>
  <joint name="right_middle_force_sensor_2_joint" type="fixed">
    <origin xyz="-0.0090859 0.040963 -0.0061003" rpy="2.7687 -1.5708 3.885" />
    <parent link="right_middle_2" />
    <child link="right_middle_force_sensor_2" />
    <axis xyz="0 0 0" />
  </joint>
  <joint name="right_middle_force_sensor_3_joint" type="fixed">
    <origin xyz="-0.0098294 0.056051 -0.0061006" rpy="2.4672 -1.5708 3.14" />
    <parent link="right_middle_2" />
    <child link="right_middle_force_sensor_3" />
    <axis xyz="0 0 0" />
  </joint>
  <joint name="right_middle_force_sensor_1_joint" type="fixed">
    <origin xyz="-0.012046 0.019649 -0.006651" rpy="2.9295 -1.5708 3.14" />
    <parent link="right_middle_1" />
    <child link="right_middle_force_sensor_1" />
    <axis xyz="0 0 0" />
  </joint>
  <joint name="right_ring_1_joint" type="revolute">
    <origin xyz="0.0045302 0.00056467 0.15683" rpy="1.5184 0 -1.5708" />
    <parent link="right_hand_base" />
    <child link="right_ring_1" />
    <axis xyz="0 0 1" />
    <limit lower="0" upper="1.4381" effort="10" velocity="1" />
  </joint>
  <joint name="right_ring_2_joint" type="revolute">
    <origin xyz="-0.0034259 0.032596 -0.00055" rpy="0 0 0" />
    <parent link="right_ring_1" />
    <child link="right_ring_2" />
    <axis xyz="0 0 1" />
    <limit lower="0" upper="3.14" effort="10" velocity="1" />
    <mimic joint="right_ring_1_joint" multiplier="1.0843" offset="0" />
  </joint>
  <joint name="right_ring_force_sensor_2_joint" type="fixed">
    <origin xyz="-0.00816549212353353 0.0374457610846523 -0.00607949056508933" rpy="1.57079632679487 -1.51508890383765 -1.22202982373572" />
    <parent link="right_ring_2" />
    <child link="right_ring_force_sensor_2" />
    <axis xyz="0 0 0" />
  </joint>
  <joint name="right_ring_force_sensor_3_joint" type="fixed">
    <origin xyz="-0.00862372785817732 0.0525719273258207 -0.00609538761271226" rpy="1.57079632679487 -1.50247215376038 -2.26922737493233" />
    <parent link="right_ring_2" />
    <child link="right_ring_force_sensor_3" />
    <axis xyz="0 0 0" />
  </joint>
  <joint name="right_ring_force_sensor_1_joint" type="fixed">
    <origin xyz="-0.0120461582060112 0.019648547178991 -0.00665098451502209" rpy="1.57079632679491 -1.51723862304532 -1.78288465285967" />
    <parent link="right_ring_1" />
    <child link="right_ring_force_sensor_1" />
    <axis xyz="0 0 0" />
  </joint>
  <joint name="right_little_1_joint" type="revolute">
    <origin xyz="0.025916 0.00056467 0.15365" rpy="1.4661 0 -1.5708" />
    <parent link="right_hand_base" />
    <child link="right_little_1" />
    <axis xyz="0 0 1" />
    <limit lower="0" upper="1.4381" effort="10" velocity="1" />
  </joint>
  <joint name="right_little_2_joint" type="revolute">
    <origin xyz="-0.0034259 0.032596 -0.00055" rpy="0 0 0" />
    <parent link="right_little_1" />
    <child link="right_little_2" />
    <axis xyz="0 0 1" />
    <limit lower="0" upper="3.14" effort="10" velocity="1" />
    <mimic joint="right_little_1_joint" multiplier="1.0843" offset="0" />
  </joint>
  <joint name="right_little_force_sensor_2_joint" type="fixed">
    <origin xyz="-0.00645123763174135 0.0276833479200767 -0.00611719352979621" rpy="1.57079632679488 -1.45969392221055 -1.22888814145719" />
    <parent link="right_little_2" />
    <child link="right_little_force_sensor_2" />
    <axis xyz="0 0 0" />
  </joint>
  <joint name="right_little_force_sensor_3_joint" type="fixed">
    <origin xyz="-0.00639723214432697 0.042706921918282 -0.00611537168168175" rpy="1.5707963267949 -1.43362674619531 -2.2760856926538" />
    <parent link="right_little_2" />
    <child link="right_little_force_sensor_3" />
    <axis xyz="0 0 0" />
  </joint>
  <joint name="right_little_force_sensor_1_joint" type="fixed">
    <origin xyz="-0.0120461582060113 0.0196485471789908 -0.00665098451502223" rpy="1.5707963267949 -1.4636944932668 -1.78288465285966" />
    <parent link="right_little_1" />
    <child link="right_little_force_sensor_1" />
    <axis xyz="0 0 0" />
  </joint>
</robot>